Workbook

Sheet Compras 2026
A1: =SUBTOTAL(3,A3:A1095) -> 204 | D1: =SUBTOTAL(9,D3:D896) -> 1.7419035e+08 | I1: =SUBTOTAL(3,I3:I500) -> 118 | J1: =SUBTOTAL(3,J3:J500) -> 121 | N1: =SUBTOTAL(3,N3:N896) -> 82 | O1: =COUNTIF(O3:O301,"FINALIZADO") -> 82
A2: PROCESSO N° | B2: DESCRIÇÃO | C2: DATA DE CRIAÇÃO | D2: VALOR PREVISTO | E2: FONTE DE RECURSO | F2: MODALIDADE | G2: DATA DO PREGÃO | H2: CONTRATO ASSINADO | I2: EMPENHO ASSINADO | J2: EMPENHO E CONTRATO ENVIADO AO FORNECEDOR (DATA) | K2: PRAZO DE ENTREGA (DIAS) | L2: DATA PREV. DE ENTREGA | M2: COBRADO ENTREGA NO DIA | N2: MATERIAL ENTREGUE (DATA) | O2: SITUAÇÃO | P2: OBSERVAÇÃO
A3: 23.536.933-8 | B3: Dispensa de menor valor - Dispensa de contratação de prestação de serviço de Dosimetria, para atender a UETC Tarumã da Polícia Científica do Paraná | C3: 45715 | D3: 10560 | E3: CUSTEIO | F3: Dispensa de Licitação | H3: 45839 | I3: 45848 | J3: 45852 | K3: 30 | L3: =IF(ISBLANK(J3), "", SUM(J3, K3)) -> 45882 | N3: 45839 | O3: FINALIZADO
A4: 23.577.593-0 | B4: Contratação de Serviço de empresa especializada em lavagem de roupa hospitalar - Lavanderia | C4: 45714 | D4: 1778400 | E4: CUSTEIO | F4: Licitação | G4: 45875 | H4: 45932 | I4: 45951 | J4: 45951 | K4: 30 | L4: =IF(ISBLANK(J4), "", SUM(J4, K4)) -> 45981 | N4: 45981 | O4: FINALIZADO
A5: 23.432.467-5 | B5: [Verba Parlamentar Moro] Aquisição de Pipetador Automático para preparo de placas para a SGMF | C5: 45734 | D5: 531310 | E5: CUSTEIO | F5: Inexigibilidade | K5: 30 | L5: =IF(ISBLANK(J5), "", SUM(J5, K5)) | O5: ARQUIVADO
A6: 23.711.290-3 | B6: Dispensa de Licitação - Aquisição de Maleta de Perícia tipo 02, para atender as necessidades da Polícia Científica do Paraná, através do Convênio Federal No 936068/2022, No Processo: 08020002865202206 | C6: 45750 | D6: 106123 | E6: INVESTIMENTO | F6: Dispensa de Licitação | H6: 45903 | I6: 45922 | J6: 45923 | K6: 90 | L6: =IF(ISBLANK(J6), "", SUM(J6, K6)) -> 46013 | M6: 45992 | O6: TRAMITANDO
A7: 23.336.634-0 | B7: Contratação do serviço de ampliação da rede de gases especiais visando a instalação de novos equipamentos laboratoriais na UETC Curitiba - Tarumã | C7: 45674 | D7: 171111.52 | E7: CUSTEIO | F7: Licitação | H7: 45917 | I7: 45937 | J7: 45936 | K7: 15 | L7: =IF(ISBLANK(J7), "", SUM(J7, K7)) -> 45951 | N7: 45951 | O7: FINALIZADO
A8: 23.356.092-8 | B8: Aquisição de “Kits de Controle de Acesso”, para atender a demanda da Divisão de Custódia de Vestígios da Polícia Científica do Paraná | C8: 45678 | D8: 193026.4 | E8: INVESTIMENTO | F8: Licitação | K8: 30 | L8: =IF(ISBLANK(J8), "", SUM(J8, K8)) | O8: TRAMITANDO
A9: 23.708.709-7 | B9: Solicita abertura para aquisição de 60 Purificadores de água e refil de filtro, a fim de atender as demandas da Polícia Científica do Paraná. | C9: 45751 | D9: 85981.41 | E9: INVESTIMENTO | F9: Licitação | K9: 30 | L9: =IF(ISBLANK(J9), "", SUM(J9, K9)) | O9: TRAMITANDO
A10: 23.822.468-3 | B10: Contratação de empresa especializada na prestação de serviços de locação de veículos adaptados para transporte de cadáveres (COTRANS) - o protocolo que correu o processo licitatório, 22.469.724-4, foi arquivado na SEAP. | C10: 45763 | D10: 33480720 | E10: CUSTEIO | F10: Licitação | G10: 45702 | H10: 45820 | I10: 45868 | J10: 45821 | K10: 60 | L10: =IF(ISBLANK(J10), "", SUM(J10, K10)) -> 45881 | O10: TRAMITANDO
A11: 23.750.119-5 | B11: SEDCA Aquisição de uma Plataforma de Processamento Rápido de DNA | C11: 45747 | D11: 990000 | E11: INVESTIMENTO | F11: Inexigibilidade | H11: 45999 | I11: 46003 | J11: 46003 | K11: 30 | L11: =IF(ISBLANK(J11), "", SUM(J11, K11)) -> 46033 | O11: TRAMITANDO
A12: 23.391.860-1 | B12: SRP Coffee Break - Aquisição através do Registro de Preço do PE 494/2023, na modalidade PARTICIPANTE, de Serviço de Coffee Break para atender as necessidades da Unidade de Execução Técnico-Científica de Curitiba da Polícia Científica do Paraná. VALIDADE DA ATA 23/09/2025 | C12: 45686 | D12: 50000 | E12: CUSTEIO | F12: SRP Estadual | G12: 45946 | H12: 45733 | I12: 45748 | J12: 45756 | K12: 360 | L12: =IF(ISBLANK(J12), "", SUM(J12, K12)) -> 46116 | N12: 45751 | O12: FINALIZADO
A13: 23.384.464-0 | B13: AQUISIÇÃO DE SOLUÇÕES TAMPÃO E KCl, VIA PREGÃO ELETRÔNICO 851/2023 LOTES 01, 02 e 03, VALIDADE DA ATA: 19/02/2025, NA MODALIDADE PARTICIPANTE, PARA SUPRIR A DEMANDA DOS LABORATÓRIOS FORENSES DA POLÍCIA CIENTÍFICA DO PARANÁ. | C13: 45688 | D13: 233.25 | E13: CUSTEIO | F13: SRP Estadual | L13: =IF(ISBLANK(J13), "", SUM(J13, K13)) | O13: ARQUIVADO
A14: 23.427.285-3 | B14: SRP Máscara e Avental Descartável - Aquisição através do Registro de Preço do PE 706/2024, na modalidade PARTICIPANTE, de Máscara e Avental Descartável para atender as necessidades das unidades da Polícia Científica do Paraná. | C14: 45698 | D14: 17473 | E14: CUSTEIO | F14: SRP Estadual | G14: 46044 | I14: 45702 | J14: 45786 | K14: 30 | L14: =IF(ISBLANK(J14), "", SUM(J14, K14)) -> 45816 | M14: 45805 | N14: 45833 | O14: FINALIZADO
A15: 23.549.843-0 | B15: SRP Insumos de Laboratórios - Aquisição através do Registro de Preço do PE 163/2023, na modalidade PARTICIPANTE de Insumos de Laboratórios para atender as unidades da Polícia Científica do Paraná. VALIDADE DA ATA: 17/02/2026 | C15: 45712 | D15: 68276.4 | E15: CUSTEIO | F15: SRP Estadual | I15: 45806 | J15: 45812 | K15: 15 | L15: =IF(ISBLANK(J15), "", SUM(J15, K15)) -> 45827 | M15: 45910 | N15: 45915 | O15: FINALIZADO
A16: 23.539.216-0 | B16: Aquisição de Câmaras Frias pelo SRP no 1388/2024. 7 Unidades: 1 Seção Ambiental, 1 Telêmaco Borba, 3 Toledo, 1 Maringá e 1 Paranaguá | C16: 45735 | D16: 292600 | E16: INVESTIMENTO | F16: SRP Estadual | I16: 45800 | J16: 45792 | K16: 45 | L16: =IF(ISBLANK(J16), "", SUM(J16, K16)) -> 45837 | M16: 45862 | N16: 45867 | O16: FINALIZADO
A17: 23.726.102-0 | B17: SRP Papel Sulfite A4 - Aquisição através do Registro de Preço do PE 33/2024, na modalidade PARTICIPANTE, de Papel Sulfite A4 para atender as necessidades das unidades da Polícia Científica do Paraná. | C17: 45743 | D17: 19470 | E17: CUSTEIO | F17: SRP Estadual | I17: 45775 | J17: 45826 | K17: 30 | L17: =IF(ISBLANK(J17), "", SUM(J17, K17)) -> 45856 | N17: 45846 | O17: FINALIZADO
A18: 23.814.144-3 | B18: SRP Almoxarife - Contratação através do Registro de Preço do PE 1934/2024, na modalidade PARTICIPANTE, de Posto, Almoxarife, 40 horas semanais, De segunda a sexta para atender as necessidades do Almoxarifado Central da Polícia Científica do Paraná. | C18: 45762 | D18: 57317.76 | E18: CUSTEIO | F18: SRP Estadual | L18: =IF(ISBLANK(J18), "", SUM(J18, K18)) | O18: ARQUIVADO
A19: 23.852.416-4 | B19: SRP Água Mineral - Aquisição através do Registro de Preço do PE 1089/2024 na modalidade PARTICIPANTE, de Água Mineral para atender as necessidades das unidades da Polícia Científica do Paraná. VALIDADE DA ATA: 07/04/2026 | C19: 45763 | D19: 89853.91 | E19: CUSTEIO | F19: SRP Estadual | I19: 45840 | J19: 45852 | K19: 10 | L19: =IF(ISBLANK(J19), "", SUM(J19, K19)) -> 45862 | N19: 45862 | O19: FINALIZADO
A20: 23.759.626-9 | B20: Adesão em ATA DE REGISTRO DE PREÇO da PCP-SC, para aquisição de álcool metílico, álcool isopropílico e luminol. | C20: 45755 | D20: 2375 | E20: CUSTEIO | F20: SRP Estadual (Carona) | H20: 45852 | I20: 45883 | J20: 45852 | K20: 60 | L20: =IF(ISBLANK(J20), "", SUM(J20, K20)) -> 45912 | M20: 45890 | N20: 45887 | O20: FINALIZADO
A21: 23.529.878-3 | B21: Trata-se de abertura de dispensa de licitação para aquisição de embalagem simples. | C21: 45713 | D21: 53179.5 | E21: CUSTEIO | F21: Dispensa de Licitação | I21: 45777 | J21: 45784 | K21: 30 | L21: =IF(ISBLANK(J21), "", SUM(J21, K21)) -> 45814 | N21: 45799 | O21: FINALIZADO
A22: 23.550.851-6 | B22: dispensa eletrônica de licitação para aquisição de insumos para a realização de exames de identificação veicular, Em Aço Rápido; lixa, graxa, removedor de esmalte (acetona) estopa | C22: 45715 | D22: 51776 | E22: CUSTEIO | F22: Dispensa de Licitação | I22: 45792 | J22: 45796 | K22: 30 | L22: =IF(ISBLANK(J22), "", SUM(J22, K22)) -> 45826 | N22: 45824 | O22: FINALIZADO
A23: 23.590.694-5 | B23: dispensa eletrônica de processo licitatório, de Artigos de Higiene Pessoal - Sabonete Líquido | C23: 45722 | D23: 16271.44 | E23: CUSTEIO | F23: Dispensa de Licitação | I23: 45786 | J23: 45792 | K23: 30 | L23: =IF(ISBLANK(J23), "", SUM(J23, K23)) -> 45822 | N23: 45804 | O23: FINALIZADO
A24: 23.444.059-4 | B24: [Verba Parlamentar - Moro] - Aquisição de Insumos para o Analisador Genético 3500 | C24: 45692 | D24: 360551.24 | E24: CUSTEIO | F24: Inexigibilidade | L24: =IF(ISBLANK(J24), "", SUM(J24, K24)) | O24: ARQUIVADO
A25: 23.711.352-7 | B25: [Verba Parlamentar - Moro] - Aquisição Sequenciador com Sistema de Eletroforese capilar | C25: 45741 | D25: 1538000 | E25: CUSTEIO | F25: Inexigibilidade | K25: 90 | L25: =IF(ISBLANK(J25), "", SUM(J25, K25)) | O25: ARQUIVADO
A26: 23.678.445-2 | B26: [Emenda Parlamentar - Sérgio Moro] Aquisição de um moinho moedor de ossos | C26: 45734 | D26: 434305.84 | E26: CUSTEIO | F26: Inexigibilidade | K26: 90 | L26: =IF(ISBLANK(J26), "", SUM(J26, K26)) | O26: ARQUIVADO
A27: 23.503.010-1 | B27: SRP CAIXA VAZADA - AQUISIÇÃO ATRAVÉS DO REGISTRO DE PREÇO DO PE 979/2023, NA MODALIDADE PARTICIPANTE, DE CAIXA VAZADA, COR: AZUL, CAPACIDADE: 49 LITROS | C27: 45702 | D27: 6480 | E27: CUSTEIO | F27: SRP Estadual | G27: 46003 | I27: 45709 | J27: 45715 | K27: 30 | L27: =IF(ISBLANK(J27), "", SUM(J27, K27)) -> 45745 | N27: 45761 | O27: FINALIZADO
A28: 23.541.254-3 | B28: SRP Reagentes Químicos - Aquisição através do Registro de Preço do PE 975/2023, na modalidade PARTICIPANTE de Reagentes Químicos para atender as unidades da Polícia Científica do Paraná. VALIDADE DA ATA: 28/05/2025 | C28: 45712 | D28: 25816.46 | E28: CUSTEIO | F28: SRP Estadual | I28: 45721 | J28: 45733 | K28: 30 | L28: =IF(ISBLANK(J28), "", SUM(J28, K28)) -> 45763 | M28: 45861 | N28: 45910 | O28: FINALIZADO
A29: 23.581.473-0 | B29: SRP Bandeiras - Aquisição através do Registro de Preço do PE 449/2023, na modalidade PARTICIPANTE, de Bandeiras para atender as necessidades das unidades da Polícia Científica do Paraná. | C29: 45717 | D29: 4666 | E29: CUSTEIO | F29: SRP Estadual | G29: 46066 | I29: 45729 | J29: 45733 | K29: 30 | L29: =IF(ISBLANK(J29), "", SUM(J29, K29)) -> 45763 | N29: 45744 | O29: FINALIZADO
A30: 23.659.354-1 | B30: SRP Envelope, TIPO: Saco, COR: Branca - Aquisição através do Registro de Preço do PE 25/2023, na modalidade PARTICIPANTE, de Envelope, TIPO: Saco, COR: Branca para atender as necessidades das unidades da Polícia Científica do Paraná. | C30: 45733 | D30: 192 | E30: CUSTEIO | F30: SRP Estadual | G30: 46007 | I30: 45737 | J30: 45740 | K30: 30 | L30: =IF(ISBLANK(J30), "", SUM(J30, K30)) -> 45770 | N30: 45775 | O30: FINALIZADO
A31: 23.650.629-0 | B31: SRP Caneta Esferográfica - Aquisição através do Registro de Preço do PE 28/2023, na modalidade PARTICIPANTE, de Caneta Esferográfica para atender as necessidades das unidades da Polícia Científica do Paraná. | C31: 45729 | D31: 976.92 | E31: CUSTEIO | F31: SRP Estadual | I31: 45736 | J31: 45740 | K31: 30 | L31: =IF(ISBLANK(J31), "", SUM(J31, K31)) -> 45770 | N31: 45772 | O31: FINALIZADO
A32: 23.642.186-4 | B32: SRP Sabão em Pó, Limpa Vidros e Lustra Móveis - Aquisição através do Registro de Preço do PE 113/2024, na modalidade PARTICIPANTE, de Sabão em Pó, Limpa Vidros e Lustra Móveis | C32: 45728 | D32: 1631.75 | E32: CUSTEIO | F32: SRP Estadual | I32: 45740 | J32: 45748 | K32: 30 | L32: =IF(ISBLANK(J32), "", SUM(J32, K32)) -> 45778 | N32: 45803 | O32: FINALIZADO
A33: 23.574.455-4 | B33: SRP Materiais Diversos para Laboratório - Aquisição através do Registro de Preço do PE 747/2023, na modalidade PARTICIPANTE, de Materiais Diversos para Laboratório para atender as necessidades das unidades da Polícia Científica do Paraná. | C33: 45716 | D33: 11757.8 | E33: CUSTEIO | F33: SRP Estadual | I33: 45729 | J33: 45770 | K33: 30 | L33: =IF(ISBLANK(J33), "", SUM(J33, K33)) -> 45800 | M33: 45834 | N33: 45839 | O33: FINALIZADO
A34: 23.326.534-9 | B34: SRP CARONA - Adesão de Aquisição através do Registro de Preço do PE 185/2024, de aquisição de Seringa, Descartável, Estéril, 20ml (sem agulha | C34: 45673 | D34: 7000 | E34: CUSTEIO | F34: SRP Estadual (Carona) | G34: 46006 | I34: 45686 | J34: 45692 | K34: 30 | L34: =IF(ISBLANK(J34), "", SUM(J34, K34)) -> 45722 | N34: 45701 | O34: FINALIZADO
A35: 23.468.057-9 | B35: SRP Água Sanitária e Desodorizador de Ambiente - Aquisição através do Registro de Preço do PE 112/2024, na modalidade PARTICIPANTE, de Água Sanitária e Desodorizador de Ambiente para atender as necessidades das unidades da Polícia Científica do Paraná. VALIDADE DA ATA: 02/02/2026 | C35: 45698 | D35: 3078.15 | E35: CUSTEIO | F35: SRP Estadual | G35: 46055 | I35: 45702 | J35: 45722 | K35: 30 | L35: =IF(ISBLANK(J35), "", SUM(J35, K35)) -> 45752 | N35: 45730 | O35: FINALIZADO
A36: 23.518.554-7 | B36: SRP Material de Limpeza - Grupo I - Aquisição através do Registro de Preço do PE 1026/2023, na modalidade PARTICIPANTE de Material de Limpeza - Grupo I - Escova, Pá, desentupidor . VALIDADE DA ATA: 09/10/2025 | C36: 45705 | D36: 1301.91 | E36: CUSTEIO | F36: SRP Estadual | G36: 45939 | I36: 45707 | J36: 45723 | K36: 30 | L36: =IF(ISBLANK(J36), "", SUM(J36, K36)) -> 45753 | N36: 45737 | O36: FINALIZADO
A37: 23.443.596-5 | B37: SRP Caixa Arquivo - Aquisição através do Registro de Preço do PE 27/2023, na modalidade PARTICIPANTE, de Caixa Arquivo para atender as necessidades das unidades da Polícia Científica do Paraná. VALIDADE DA ATA: 27/02/2025 | C37: 45692 | D37: 2862 | E37: CUSTEIO | F37: SRP Estadual | G37: 45715 | I37: 45700 | J37: 45708 | K37: 30 | L37: =IF(ISBLANK(J37), "", SUM(J37, K37)) -> 45738 | N37: 45728 | O37: FINALIZADO
A38: 23.510.701-5 | B38: SRP Garrafa Térmica - Aquisição através do Registro de Preço do PE 366/2023, na modalidade PARTICIPANTE de Garrafa Térmica 1,8 Litros para atender as unidades da Polícia Científica do Paraná. VALIDADE DA ATA: 01/09/2025 | C38: 45705 | D38: 2847.5 | E38: CUSTEIO | F38: SRP Estadual | G38: 45901 | I38: 45716 | J38: 45722 | K38: 30 | L38: =IF(ISBLANK(J38), "", SUM(J38, K38)) -> 45752 | N38: 45737 | O38: FINALIZADO
A39: 23.460.149-0 | B39: SRP Luva Nitrílica - Aquisição através do Registro de Preço do PE 747/2023, na modalidade PARTICIPANTE, de Luva Nitrílica para atender as necessidades das unidades da Polícia Científica do Paraná. VALIDADE DA ATA: 29/04/2025 | C39: 45695 | D39: 99500.4 | E39: CUSTEIO | F39: SRP Estadual | G39: 45776 | I39: 45701 | J39: 45729 | K39: 30 | L39: =IF(ISBLANK(J39), "", SUM(J39, K39)) -> 45759 | N39: 45742 | O39: FINALIZADO
A40: 23.456.626-1 | B40: Solicitação de compra por dispensa de licitação de envelopes cartão. | C40: 45735 | D40: 2600 | E40: CUSTEIO | F40: Dispensa de Licitação | I40: 45818 | J40: 45824 | K40: 30 | L40: =IF(ISBLANK(J40), "", SUM(J40, K40)) -> 45854 | N40: 45847 | O40: FINALIZADO
...

Sheet Compras 2025
A1: =SUBTOTAL(3,A3:A1095) -> 204 | D1: =SUBTOTAL(9,D3:D1094) -> 1.7419035e+08 | I1: =SUBTOTAL(3,I3:I500) -> 110 | J1: =SUBTOTAL(3,J3:J500) -> 110 | N1: =SUBTOTAL(3,N3:N1094) -> 78 | O1: =COUNTIF(O3:O499,"FINALIZADO") -> 78
A2: PROCESSO N° | B2: DESCRIÇÃO | C2: DATA DE CRIAÇÃO | D2: VALOR PREVISTO | E2: FONTE DE RECURSO | F2: MODALIDADE | G2: DATA DO PREGÃO | H2: CONTRATO ASSINADO | I2: EMPENHO ASSINADO | J2: EMPENHO E CONTRATO ENVIADO AO FORNECEDOR (DATA) | K2: PRAZO DE ENTREGA (DIAS) | L2: DATA PREV. DE ENTREGA | M2: COBRADO ENTREGA NO DIA | N2: MATERIAL ENTREGUE (DATA) | O2: SITUAÇÃO | P2: OBSERVAÇÃO
A3: 23.536.933-8 | B3: Dispensa de menor valor - Dispensa de contratação de prestação de serviço de Dosimetria, para atender a UETC Tarumã da Polícia Científica do Paraná | C3: 45715 | D3: 10560 | E3: CUSTEIO | F3: Dispensa de Licitação | H3: 45839 | I3: 45848 | J3: 45852 | K3: 30 | L3: =IF(ISBLANK(J3), "", SUM(J3, K3)) -> 45882 | N3: 45839 | O3: FINALIZADO
A4: 23.577.593-0 | B4: Contratação de Serviço de empresa especializada em lavagem de roupa hospitalar - Lavanderia | C4: 45714 | D4: 1778400 | E4: CUSTEIO | F4: Licitação | G4: 45875 | H4: 45932 | I4: 45951 | J4: 45951 | K4: 30 | L4: =IF(ISBLANK(J4), "", SUM(J4, K4)) -> 45981 | N4: 45981 | O4: FINALIZADO
A5: 23.432.467-5 | B5: [Verba Parlamentar Moro] Aquisição de Pipetador Automático para preparo de placas para a SGMF | C5: 45734 | D5: 531310 | E5: CUSTEIO | F5: Inexigibilidade | K5: 30 | L5: =IF(ISBLANK(J5), "", SUM(J5, K5)) | O5: TRAMITANDO
A6: 23.711.290-3 | B6: Dispensa de Licitação - Aquisição de Maleta de Perícia tipo 02, para atender as necessidades da Polícia Científica do Paraná, através do Convênio Federal No 936068/2022, No Processo: 08020002865202206 | C6: 45750 | D6: 106123 | E6: INVESTIMENTO | F6: Dispensa de Licitação | H6: 45903 | I6: 45922 | J6: 45923 | K6: 90 | L6: =IF(ISBLANK(J6), "", SUM(J6, K6)) -> 46013 | M6: 45992 | O6: TRAMITANDO
A7: 23.336.634-0 | B7: Contratação do serviço de ampliação da rede de gases especiais visando a instalação de novos equipamentos laboratoriais na UETC Curitiba - Tarumã | C7: 45674 | D7: 171111.52 | E7: CUSTEIO | F7: Licitação | H7: 45917 | I7: 45937 | J7: 45936 | K7: 15 | L7: =IF(ISBLANK(J7), "", SUM(J7, K7)) -> 45951 | N7: 45951 | O7: FINALIZADO
A8: 23.356.092-8 | B8: Aquisição de “Kits de Controle de Acesso”, para atender a demanda da Divisão de Custódia de Vestígios da Polícia Científica do Paraná | C8: 45678 | D8: 193026.4 | E8: INVESTIMENTO | F8: Licitação | K8: 30 | L8: =IF(ISBLANK(J8), "", SUM(J8, K8)) | O8: TRAMITANDO
A9: 23.708.709-7 | B9: Solicita abertura para aquisição de 60 Purificadores de água e refil de filtro, a fim de atender as demandas da Polícia Científica do Paraná. | C9: 45751 | D9: 85981.41 | E9: INVESTIMENTO | F9: Licitação | K9: 30 | L9: =IF(ISBLANK(J9), "", SUM(J9, K9)) | O9: TRAMITANDO
A10: 23.822.468-3 | B10: Contratação de empresa especializada na prestação de serviços de locação de veículos adaptados para transporte de cadáveres (COTRANS) - o protocolo que correu o processo licitatório, 22.469.724-4, foi arquivado na SEAP. | C10: 45763 | D10: 33480720 | E10: CUSTEIO | F10: Licitação | G10: 45702 | H10: 45820 | I10: 45868 | J10: 45821 | K10: 60 | L10: =IF(ISBLANK(J10), "", SUM(J10, K10)) -> 45881 | O10: TRAMITANDO
A11: 23.750.119-5 | B11: SEDCA Aquisição de uma Plataforma de Processamento Rápido de DNA | C11: 45747 | D11: 990000 | E11: INVESTIMENTO | F11: Inexigibilidade | H11: 45999 | K11: 30 | L11: =IF(ISBLANK(J11), "", SUM(J11, K11)) | O11: TRAMITANDO | P11: 25/06/2025 - Enviado ao SESP/NFS/OR para emissão das informações financeiras
A12: 23.391.860-1 | B12: SRP Coffee Break - Aquisição através do Registro de Preço do PE 494/2023, na modalidade PARTICIPANTE, de Serviço de Coffee Break para atender as necessidades da Unidade de Execução Técnico-Científica de Curitiba da Polícia Científica do Paraná. VALIDADE DA ATA 23/09/2025 | C12: 45686 | D12: 50000 | E12: CUSTEIO | F12: SRP Estadual | G12: 45946 | H12: 45733 | I12: 45748 | J12: 45756 | K12: 360 | L12: =IF(ISBLANK(J12), "", SUM(J12, K12)) -> 46116 | N12: 45751 | O12: FINALIZADO
A13: 23.384.464-0 | B13: AQUISIÇÃO DE SOLUÇÕES TAMPÃO E KCl, VIA PREGÃO ELETRÔNICO 851/2023 LOTES 01, 02 e 03, VALIDADE DA ATA: 19/02/2025, NA MODALIDADE PARTICIPANTE, PARA SUPRIR A DEMANDA DOS LABORATÓRIOS FORENSES DA POLÍCIA CIENTÍFICA DO PARANÁ. | C13: 45688 | D13: 233.25 | E13: CUSTEIO | F13: SRP Estadual | L13: =IF(ISBLANK(J13), "", SUM(J13, K13)) | O13: ARQUIVADO
A14: 23.427.285-3 | B14: SRP Máscara e Avental Descartável - Aquisição através do Registro de Preço do PE 706/2024, na modalidade PARTICIPANTE, de Máscara e Avental Descartável para atender as necessidades das unidades da Polícia Científica do Paraná. | C14: 45698 | D14: 17473 | E14: CUSTEIO | F14: SRP Estadual | G14: 46044 | I14: 45702 | J14: 45786 | K14: 30 | L14: =IF(ISBLANK(J14), "", SUM(J14, K14)) -> 45816 | M14: 45805 | N14: 45833 | O14: FINALIZADO
A15: 23.549.843-0 | B15: SRP Insumos de Laboratórios - Aquisição através do Registro de Preço do PE 163/2023, na modalidade PARTICIPANTE de Insumos de Laboratórios para atender as unidades da Polícia Científica do Paraná. VALIDADE DA ATA: 17/02/2026 | C15: 45712 | D15: 68276.4 | E15: CUSTEIO | F15: SRP Estadual | I15: 45806 | J15: 45812 | K15: 15 | L15: =IF(ISBLANK(J15), "", SUM(J15, K15)) -> 45827 | M15: 45910 | N15: 45915 | O15: FINALIZADO
A16: 23.539.216-0 | B16: Aquisição de Câmaras Frias pelo SRP no 1388/2024. 7 Unidades: 1 Seção Ambiental, 1 Telêmaco Borba, 3 Toledo, 1 Maringá e 1 Paranaguá | C16: 45735 | D16: 292600 | E16: INVESTIMENTO | F16: SRP Estadual | I16: 45800 | J16: 45792 | K16: 45 | L16: =IF(ISBLANK(J16), "", SUM(J16, K16)) -> 45837 | M16: 45862 | N16: 45867 | O16: FINALIZADO | P16: 29/07/2025 - Ja entregue Telemaco Borba, Segundo Beatriz
A17: 23.726.102-0 | B17: SRP Papel Sulfite A4 - Aquisição através do Registro de Preço do PE 33/2024, na modalidade PARTICIPANTE, de Papel Sulfite A4 para atender as necessidades das unidades da Polícia Científica do Paraná. | C17: 45743 | D17: 19470 | E17: CUSTEIO | F17: SRP Estadual | I17: 45775 | J17: 45826 | K17: 30 | L17: =IF(ISBLANK(J17), "", SUM(J17, K17)) -> 45856 | N17: 45846 | O17: FINALIZADO
A18: 23.814.144-3 | B18: SRP Almoxarife - Contratação através do Registro de Preço do PE 1934/2024, na modalidade PARTICIPANTE, de Posto, Almoxarife, 40 horas semanais, De segunda a sexta para atender as necessidades do Almoxarifado Central da Polícia Científica do Paraná. | C18: 45762 | D18: 57317.76 | E18: CUSTEIO | F18: SRP Estadual | L18: =IF(ISBLANK(J18), "", SUM(J18, K18)) | O18: ARQUIVADO
A19: 23.852.416-4 | B19: SRP Água Mineral - Aquisição através do Registro de Preço do PE 1089/2024 na modalidade PARTICIPANTE, de Água Mineral para atender as necessidades das unidades da Polícia Científica do Paraná. VALIDADE DA ATA: 07/04/2026 | C19: 45763 | D19: 89853.91 | E19: CUSTEIO | F19: SRP Estadual | I19: 45840 | J19: 45852 | K19: 10 | L19: =IF(ISBLANK(J19), "", SUM(J19, K19)) -> 45862 | N19: 45862 | O19: FINALIZADO
A20: 23.759.626-9 | B20: Adesão em ATA DE REGISTRO DE PREÇO da PCP-SC, para aquisição de álcool metílico, álcool isopropílico e luminol. | C20: 45755 | D20: 2375 | E20: CUSTEIO | F20: SRP Estadual (Carona) | H20: 45852 | I20: 45883 | J20: 45852 | K20: 60 | L20: =IF(ISBLANK(J20), "", SUM(J20, K20)) -> 45912 | M20: 45890 | N20: 45887 | O20: FINALIZADO
A21: 23.529.878-3 | B21: Trata-se de abertura de dispensa de licitação para aquisição de embalagem simples. | C21: 45713 | D21: 53179.5 | E21: CUSTEIO | F21: Dispensa de Licitação | I21: 45777 | J21: 45784 | K21: 30 | L21: =IF(ISBLANK(J21), "", SUM(J21, K21)) -> 45814 | N21: 45799 | O21: FINALIZADO
A22: 23.550.851-6 | B22: dispensa eletrônica de licitação para aquisição de insumos para a realização de exames de identificação veicular, Em Aço Rápido; lixa, graxa, removedor de esmalte (acetona) estopa | C22: 45715 | D22: 51776 | E22: CUSTEIO | F22: Dispensa de Licitação | I22: 45792 | J22: 45796 | K22: 30 | L22: =IF(ISBLANK(J22), "", SUM(J22, K22)) -> 45826 | N22: 45824 | O22: FINALIZADO
A23: 23.590.694-5 | B23: dispensa eletrônica de processo licitatório, de Artigos de Higiene Pessoal - Sabonete Líquido | C23: 45722 | D23: 16271.44 | E23: CUSTEIO | F23: Dispensa de Licitação | I23: 45786 | J23: 45792 | K23: 30 | L23: =IF(ISBLANK(J23), "", SUM(J23, K23)) -> 45822 | N23: 45804 | O23: FINALIZADO
A24: 23.444.059-4 | B24: [Verba Parlamentar - Moro] - Aquisição de Insumos para o Analisador Genético 3500 | C24: 45692 | D24: 360551.24 | E24: CUSTEIO | F24: Inexigibilidade | L24: =IF(ISBLANK(J24), "", SUM(J24, K24)) | O24: TRAMITANDO
A25: 23.711.352-7 | B25: [Verba Parlamentar - Moro] - Aquisição Sequenciador com Sistema de Eletroforese capilar | C25: 45741 | D25: 1538000 | E25: CUSTEIO | F25: Inexigibilidade | K25: 90 | L25: =IF(ISBLANK(J25), "", SUM(J25, K25)) | O25: TRAMITANDO
A26: 23.678.445-2 | B26: [Emenda Parlamentar - Sérgio Moro] Aquisição de um moinho moedor de ossos | C26: 45734 | D26: 434305.84 | E26: CUSTEIO | F26: Inexigibilidade | K26: 90 | L26: =IF(ISBLANK(J26), "", SUM(J26, K26)) | O26: TRAMITANDO
A27: 23.503.010-1 | B27: SRP CAIXA VAZADA - AQUISIÇÃO ATRAVÉS DO REGISTRO DE PREÇO DO PE 979/2023, NA MODALIDADE PARTICIPANTE, DE CAIXA VAZADA, COR: AZUL, CAPACIDADE: 49 LITROS | C27: 45702 | D27: 6480 | E27: CUSTEIO | F27: SRP Estadual | G27: 46003 | I27: 45709 | J27: 45715 | K27: 30 | L27: =IF(ISBLANK(J27), "", SUM(J27, K27)) -> 45745 | N27: 45761 | O27: FINALIZADO
A28: 23.541.254-3 | B28: SRP Reagentes Químicos - Aquisição através do Registro de Preço do PE 975/2023, na modalidade PARTICIPANTE de Reagentes Químicos para atender as unidades da Polícia Científica do Paraná. VALIDADE DA ATA: 28/05/2025 | C28: 45712 | D28: 25816.46 | E28: CUSTEIO | F28: SRP Estadual | I28: 45721 | J28: 45733 | K28: 30 | L28: =IF(ISBLANK(J28), "", SUM(J28, K28)) -> 45763 | M28: 45861 | N28: 45910 | O28: FINALIZADO
A29: 23.581.473-0 | B29: SRP Bandeiras - Aquisição através do Registro de Preço do PE 449/2023, na modalidade PARTICIPANTE, de Bandeiras para atender as necessidades das unidades da Polícia Científica do Paraná. | C29: 45717 | D29: 4666 | E29: CUSTEIO | F29: SRP Estadual | G29: 46066 | I29: 45729 | J29: 45733 | K29: 30 | L29: =IF(ISBLANK(J29), "", SUM(J29, K29)) -> 45763 | N29: 45744 | O29: FINALIZADO
A30: 23.659.354-1 | B30: SRP Envelope, TIPO: Saco, COR: Branca - Aquisição através do Registro de Preço do PE 25/2023, na modalidade PARTICIPANTE, de Envelope, TIPO: Saco, COR: Branca para atender as necessidades das unidades da Polícia Científica do Paraná. | C30: 45733 | D30: 192 | E30: CUSTEIO | F30: SRP Estadual | G30: 46007 | I30: 45737 | J30: 45740 | K30: 30 | L30: =IF(ISBLANK(J30), "", SUM(J30, K30)) -> 45770 | N30: 45775 | O30: FINALIZADO
A31: 23.650.629-0 | B31: SRP Caneta Esferográfica - Aquisição através do Registro de Preço do PE 28/2023, na modalidade PARTICIPANTE, de Caneta Esferográfica para atender as necessidades das unidades da Polícia Científica do Paraná. | C31: 45729 | D31: 976.92 | E31: CUSTEIO | F31: SRP Estadual | I31: 45736 | J31: 45740 | K31: 30 | L31: =IF(ISBLANK(J31), "", SUM(J31, K31)) -> 45770 | N31: 45772 | O31: FINALIZADO
A32: 23.642.186-4 | B32: SRP Sabão em Pó, Limpa Vidros e Lustra Móveis - Aquisição através do Registro de Preço do PE 113/2024, na modalidade PARTICIPANTE, de Sabão em Pó, Limpa Vidros e Lustra Móveis | C32: 45728 | D32: 1631.75 | E32: CUSTEIO | F32: SRP Estadual | I32: 45740 | J32: 45748 | K32: 30 | L32: =IF(ISBLANK(J32), "", SUM(J32, K32)) -> 45778 | N32: 45803 | O32: FINALIZADO
A33: 23.574.455-4 | B33: SRP Materiais Diversos para Laboratório - Aquisição através do Registro de Preço do PE 747/2023, na modalidade PARTICIPANTE, de Materiais Diversos para Laboratório para atender as necessidades das unidades da Polícia Científica do Paraná. | C33: 45716 | D33: 11757.8 | E33: CUSTEIO | F33: SRP Estadual | I33: 45729 | J33: 45770 | K33: 30 | L33: =IF(ISBLANK(J33), "", SUM(J33, K33)) -> 45800 | M33: 45834 | N33: 45839 | O33: FINALIZADO
A34: 23.326.534-9 | B34: SRP CARONA - Adesão de Aquisição através do Registro de Preço do PE 185/2024, de aquisição de Seringa, Descartável, Estéril, 20ml (sem agulha | C34: 45673 | D34: 7000 | E34: CUSTEIO | F34: SRP Estadual (Carona) | G34: 46006 | I34: 45686 | J34: 45692 | K34: 30 | L34: =IF(ISBLANK(J34), "", SUM(J34, K34)) -> 45722 | N34: 45701 | O34: FINALIZADO
A35: 23.468.057-9 | B35: SRP Água Sanitária e Desodorizador de Ambiente - Aquisição através do Registro de Preço do PE 112/2024, na modalidade PARTICIPANTE, de Água Sanitária e Desodorizador de Ambiente para atender as necessidades das unidades da Polícia Científica do Paraná. VALIDADE DA ATA: 02/02/2026 | C35: 45698 | D35: 3078.15 | E35: CUSTEIO | F35: SRP Estadual | G35: 46055 | I35: 45702 | J35: 45722 | K35: 30 | L35: =IF(ISBLANK(J35), "", SUM(J35, K35)) -> 45752 | N35: 45730 | O35: FINALIZADO
A36: 23.518.554-7 | B36: SRP Material de Limpeza - Grupo I - Aquisição através do Registro de Preço do PE 1026/2023, na modalidade PARTICIPANTE de Material de Limpeza - Grupo I - Escova, Pá, desentupidor . VALIDADE DA ATA: 09/10/2025 | C36: 45705 | D36: 1301.91 | E36: CUSTEIO | F36: SRP Estadual | G36: 45939 | I36: 45707 | J36: 45723 | K36: 30 | L36: =IF(ISBLANK(J36), "", SUM(J36, K36)) -> 45753 | N36: 45737 | O36: FINALIZADO
A37: 23.443.596-5 | B37: SRP Caixa Arquivo - Aquisição através do Registro de Preço do PE 27/2023, na modalidade PARTICIPANTE, de Caixa Arquivo para atender as necessidades das unidades da Polícia Científica do Paraná. VALIDADE DA ATA: 27/02/2025 | C37: 45692 | D37: 2862 | E37: CUSTEIO | F37: SRP Estadual | G37: 45715 | I37: 45700 | J37: 45708 | K37: 30 | L37: =IF(ISBLANK(J37), "", SUM(J37, K37)) -> 45738 | N37: 45728 | O37: FINALIZADO
A38: 23.510.701-5 | B38: SRP Garrafa Térmica - Aquisição através do Registro de Preço do PE 366/2023, na modalidade PARTICIPANTE de Garrafa Térmica 1,8 Litros para atender as unidades da Polícia Científica do Paraná. VALIDADE DA ATA: 01/09/2025 | C38: 45705 | D38: 2847.5 | E38: CUSTEIO | F38: SRP Estadual | G38: 45901 | I38: 45716 | J38: 45722 | K38: 30 | L38: =IF(ISBLANK(J38), "", SUM(J38, K38)) -> 45752 | N38: 45737 | O38: FINALIZADO
A39: 23.460.149-0 | B39: SRP Luva Nitrílica - Aquisição através do Registro de Preço do PE 747/2023, na modalidade PARTICIPANTE, de Luva Nitrílica para atender as necessidades das unidades da Polícia Científica do Paraná. VALIDADE DA ATA: 29/04/2025 | C39: 45695 | D39: 99500.4 | E39: CUSTEIO | F39: SRP Estadual | G39: 45776 | I39: 45701 | J39: 45729 | K39: 30 | L39: =IF(ISBLANK(J39), "", SUM(J39, K39)) -> 45759 | N39: 45742 | O39: FINALIZADO
A40: 23.456.626-1 | B40: Solicitação de compra por dispensa de licitação de envelopes cartão. | C40: 45735 | D40: 2600 | E40: CUSTEIO | F40: Dispensa de Licitação | I40: 45818 | J40: 45824 | K40: 30 | L40: =IF(ISBLANK(J40), "", SUM(J40, K40)) -> 45854 | N40: 45847 | O40: FINALIZADO
...

Sheet Compras 2024
A2: 164 | G2: R$ 109.146.876,16 | H2: 72 | I2: 69 | K2: 38 | N2: 13
A3: PROCESSO N° | B3: DESCRIÇÃO | C3: instrução | D3: UNIDADE PCP | E3: Unidade a ser atendida | F3: DATA DE CRIAÇÃO | G3: VALOR PREVISTO | H3: EMPENHO ASSINADO | I3: EMPENHO ENVIADO AO FORNECEDOR (DATA) | J3: Data Máxima de entrega | K3: MATERIAL ENTREGUE (DATA) | L3: VERBA | M3: MODALIDADE | N3: Convênio | O3: SITUAÇÃO | P3: GESTOR | Q3: FISCAL | R3: ONDE ESTÁ | S3: Desde Consulta | T3: Observações
A4: 21.104.002-5 | B4: PROGRAMA PARANÁ MAIS CIDADES - Aquisição de VTR por SRP | C4: Eduarda | D4: Grupo Auxiliar Administrativo | E4: UETC Maringa | F4: 45197 | G4: R$ 150.000,00 | L4: INVESTIMENTO | M4: REGISTRO DE PREÇO (ESTADUAL) | O4: TRAMITANDO | R4: SESP/APCP | S4: 45309 | T4: 05/12/2023 - Aguardando email de confirmação da Toyota 11/01/2023 - Considerando que não houve exito de nenhuma empresa para fornecer o veículo sedan, retorna-se ao divisional para ciência18/01/2024- Encaminhado ao PCP/DA/GAA/COMPRAS para providências
A5: 20.620.696-9 | B5: Convênio No 936068/2022 - aquisição de maletas para atendimento de local de crime (Meta 1 - etapas 1 e 2) Drone e maleta de ferramenta | C5: Eduarda | D5: CURITIBA | E5: TODAS | F5: 45093 | G5: R$ 381.353,30 | H5: 45475 | I5: 45484 | L5: INVESTIMENTO | M5: LICITAÇÃO | N5: 936.068/2022 | O5: TRAMITANDO | P5: Alexandre Guilherme de Lara | Q5: Roman Hector Abril | R5: PCP/ACF/DIR | S5: 45566 | T5: 23/08/2023 - , restitua-se os autos à PCP/DA/GAA/COMPRAS para ciência, análise e demais providências 04/10/2023 Encaminhado com adequações ao setor de licitações via Acessoria 16/11/2023 - Encontra-se no setor de licitações para abertura de procedimento licitatório 05/12/2023 - Encontra-se SESP/DG em fase de adjudicação/homologação17/05/2024- Encaminhado ao PCP/DA/GAOFS para inserção da nota de empenho11/07/2024- Encaminhado ao gestor para acompanhamento da entrega25/09/2024- Descumprimento contratual
A6: 21.585.332-2 | B6: SRP - Aquisição através do Registro de Preço do PE 25/2023, de Etiquetas Adesivas para atender a unidade da Polícia Científica do Paraná. | C6: Eduarda | D6: Grupo Auxiliar Administrativo | E6: TODAS | F6: 45308 | G6: R$ 3.595,26 | H6: 45328 | I6: 45337 | K6: 45364 | L6: CUSTEIO | M6: SRP Estadual | O6: FINALIZADO | P6: Não se aplica | Q6: Não se aplica | R6: SESP/DG/NFS | S6: 45488 | T6: 17/01/2024 - Encaminhado ao Chefe da Divisão para a análise a manifestação 16/02/2024 - Encaminhado para o setor de almoxarifado para aguardar entrega13/03/2024- Material recebido08/05/2024- Material recebido
A7: 21.585.336-5 | B7: SRP - Aquisição através do Registro de Preço do PE 1181/2022, de Material de Limpeza para atender a unidade da Polícia Científica do Paraná. | C7: Eduarda | D7: Grupo Auxiliar Administrativo | E7: TODAS | F7: 45308 | G7: R$ 727,96 | H7: 45327 | I7: 45337 | K7: 45355 | L7: CUSTEIO | M7: SRP Estadual | O7: FINALIZADO | P7: Não se aplica | Q7: Não se aplica | R7: SESP/DG/NFS | S7: 45488 | T7: 17/01/2024 - Encaminhado ao Chefe da Divisão para a análise a manifestação 16/02/2024 - Encaminhado para o setor de almoxarifado para aguardar entrega20/02/2024- Materiais recebidos
A8: 21.602.015-4 | B8: SRP - Contratação através do Registro de Preço do PE 146/2022, de prestação de serviço de locação de veículo para transporte de cadáver para atender as unidades da Polícia Científica do Paraná.VALIDADE DA ATA: 14/02/2024 | C8: Eduarda | D8: Grupo Auxiliar Administrativo | E8: TODAS | F8: 45310 | G8: R$ 504.048,00 | H8: 45384 | I8: 45385 | L8: CUSTEIO | M8: SRP Estadual | O8: ARQUIVADO | P8: Alessandro Burko Lopes | Q8: Philippe Alicio de Carvalho | R8: PCP/DA - PCP/DA/GAA/CONTRATOS | S8: 45586 | T8: 22/01/2024 - Encaminhado ao Chefe da Divisão para a análise a manifestação 19/02/2024 - Encaminhado ao SESP/APC para continuação da tramitação 15/03/2024- Encaminhado ao GAOFS para inserção de nota de empenho02/04/024- Nota de empenho inserida (ainda não foi assinada)03/04/2024- Contrato e Nota de Empenho encaminhados ao fornecedor
A9: 21.607.728-8 | B9: Dispensa de Licitação - Aquisição através de dispensa de licitação de aquisição de Tubo de Coleta Fluoretado e microtubo Eppendorf para atendimento da demanda da Polícia Científica do Paraná. DISPENSA ELETRÔNICA | C9: Eduarda | D9: Grupo Auxiliar Administrativo | E9: Laboratórios | F9: 45313 | G9: R$ 14.730,00 | H9: 45572 | I9: 45576 | J9: 45590 | K9: 45604 | L9: CUSTEIO | M9: DISPENSA ELETRÔNICA | O9: FINALIZADO | P9: Camilla Borges Gazolla | Q9: Josiane Brodzinski | R9: PCP/CWB/TAR/NECRO | S9: 45587 | T9: 30/01/2024 - Encaminhado ao Chefe do Financeiro para a atualização de informações orçamentárias 17/04/2024 - Encaminhado para SESP/APC para continuação da tramitação03/05/2024- Encaminhado ao NFS/OR para aprovação das informações orçamentárias 24/06/2024 - Encaminhado para SESP/COMPRAS para continuação da tramitação 07/08/2024 - Encaminhado para Chefe Divisional para ciência e encaminhamento a SESP/APC 12/09/2024 - Encaminhado para o GAOFS para emissão da Nota de Empenho
A10: 20.917.975-0 | B10: Solicita aquisição de um Sistema de Cromatografia Líquida acoplado a Espectrômetro de Massas Sequencial do tipo Triplo Quadrupolo (LC-MS/MS) para atender as necessidades da Seção de Toxicologia Forense | C10: Marcia | D10: Tarumã | E10: Laboratório de Toxicologia | F10: 45310 | G10: R$ 2.649.085,08 | L10: INVESTIMENTO | M10: LICITAÇÃO | O10: ARQUIVADO | P10: Carolina Schmeiske da Graça | Q10: Raquel de Oliveira Vilhena | R10: PCP/CWB/TAR/TOX | S10: 45415 | T10: 23/01/2024 - Encaminhado ao Chefe da Divisão para a análise a manifestação
A11: 21.555.888-6 | B11: Tem este o objetivo de solicitar a instauração de processo de licitação para aquisição de um Sistema de Cromatografia Gasosa Acoplado a Espectrômetro de Massas (GC/MS/MS), visando atender as necessidades de ampliação do escopo de análises analíticas realizadas pelos Laboratórios de Química Forense e Toxicologia Forense da Polícia Científica do Paraná | C11: Marcia | D11: Tarumã | E11: Laboratório de Toxicologia | F11: 45315 | G11: R$ 2.503.120,12 | L11: INVESTIMENTO | M11: LICITAÇÃO | O11: finalizado | P11: Carolina Schmeiske da Graça | Q11: Raquel de Oliveira Vilhena | R11: SESP - SESP/SL | S11: 45602 | T11: 25/01/2024 - Encaminhado ao Chefe da Divisão para a análise a manifestação08/04/2024- Encaminhado à origem para ciência e providências | U11: difícil | V11: Possibilidade de Empenho Baixa
A12: 20.575.782-1 | B12: Aquisição, através de procedimento licitatório, de duas unidades de Sistema de Espectrometria de Infravermelho com Transformada de Fourier (FTIR) para os Laboratórios de Química Forense da Polícia Científica do Paraná. | C12: Marcia | D12: Tarumã | E12: Laboratório de Química Forene | F12: 45315 | G12: R$ 900.215,75 | L12: INVESTIMENTO | M12: LICITAÇÃO | O12: TRAMITANDO | P12: Carolina Schmeiske da Graça | Q12: Raquel de Oliveira Vilhena | R12: SESP - SESP/DEST/SC | S12: 45602 | T12: 25/01/2024 - Encaminhado ao Chefe da Divisão para a análise a manifestação11/06/2024- Encaminhado à PGE para análise e deliberações 30/07/2024 - Com adequações restituído à APC para continuidade | U12: Licitado - Falta Homologar | V12: Empenho Condicional
A13: 21.599.749-9 | B13: Adesão à Ata de Registro de Preços - PE no 1883/2022, objetivando a aquisição de termômetros para suprir a demanda dos Laboratórios Forenses da Polícia Científica do Paraná.VALIDADE DA ATA: 27/05/2024 | C13: Amanda | D13: Grupo Auxiliar Administrativo | E13: Laboratórios Forenses | F13: 45310 | G13: R$ 5.034,00 | H13: 45392 | I13: 45411 | K13: 45441 | L13: CUSTEIO | M13: SRP Estadual | O13: FINALIZADO | P13: Jaqueline de Moura da Silva | Q13: Carolina Schmeiske da Graça | R13: SESP/DG/NFS | S13: 45498 | T13: 22/01/2024- Aguardando análise do Centro de Planejamento de Compras 01/03/2024- Aguardando autorização da carona04/04/2024- Encaminhado ao Chefe da Divisão para a análise a manifestação29/05/2024- Material entregue 04/06/2024- Encaminhado para liquidação e pagamento
A14: 21.634.362-0 | B14: Solicita a abertura de processo de licitação para aquisição de Café, com o intuito de atender à demanda de todas as Unidades da Polícia Científica do Paraná | C14: Raphael | D14: Grupo Auxiliar Administrativo | E14: TODAS | F14: 45317 | G14: R$ 141.057,00 | L14: CUSTEIO | M14: LICITAÇÃO | O14: ARQUIVADO | P14: Leonardo Morrissy Hostin | Q14: Mauricio Catitas de Sousa | R14: PCP/DA/GAA/COMPRAS | S14: 45582 | T14: 30/01/2024 - Encaminhado ao Chefe da Divisão para a análise a manifestação08/02/2024- Retorno devido à existência de Regitro de Preço vigente 21/03/2024- Encaminhado à PCP/DA/DIV informando o vencimento da ata09/04/2024 - Despacho do DG SESP informando que é para aguardar a liberação da ata de registro de preços. 13/09/2024 Com cancelamento dos lotes 1 e 2 do SRP, documentos e valores atualizados, enviado ao divisional, sugerindo encaminhamento ao financeiro para atualização e posterior envio ao setor de licitaçãoes17/10 - cONSIDERANDO A DIFICULDADE DO PROCESSO, ARQUIVADO (TEM QUE CONTRATAR LABORATORIO PARA ANALISAR AS AMOSTRAS) | U14: NÃO
A15: 21.592.164-6 | B15: Aquisição através de processo licitatório de papel toalha e papel higiênico para atender a demanda das unidades da Polícia Científica do Paraná. | C15: Raphael | D15: Grupo Auxiliar Administrativo | E15: TODAS | F15: 45313 | G15: R$ 109.513,75 | H15: sim | I15: 45544 | L15: CUSTEIO | M15: LICITAÇÃO | O15: TRAMITANDO | P15: Lucas de França Leviski | Q15: Mauricio Catitas de Sousa | R15: SESP/DG/NFS | S15: 45544 | T15: 22/01/2024- Encaminhado ao Chefe da Divisão para a análise e manifestação06/02/2024- Retorno devido à existência de Registro de Preço vigente 26/03/2024 - Com as negativas de participação às SRP e adequações dos documentos que se fizeram necessárias, enviado à PCP/DA/DIV para conhecimento, sugerindo encaminhamento à SESP 06/05/2024- Encaminhado ao PCP/DA/GAA/COMPRAS para providências09/09/2024- Encaminhado ao Almoxarifado para aguardar recebimento
A16: 21.588.711-1 | B16: Inexigibilidade- Manutenção Cromatógrafo gasoso | C16: Raphael | D16: PCP/CWB/TAR/TOX | E16: Seção de Toxicologia Forense | F16: 45308 | G16: R$ 98.797,40 | H16: 45463 | I16: 45468 | L16: CUSTEIO | M16: INEXIGIBILIDADE | O16: FINALIZADO | P16: Carolina Schmeiske da Graça | Q16: Dayse Fernanda de Souza | R16: PCP/CWB/TAR/TOX | S16: 45469 | T16: 30/01/2024 - Encaminhado ao Chefe da Divisão para a análise e manifestação 08/03/2024 - Encaminhado ao SESP/SC para continuação da tramitação03/04/2024- Encaminhado ao PCP/DA/GAA/COMPRAS para inclusão do ato de designação do agente de contratação20/06/2024- Nota de empenho assinada25/06/2024- Encaminhado para a gestora do contrato para acompanhamento da prestação do serviço
A17: 21.349.114-8 | B17: Dispensa de Licitação - Aquisição através de dispensa de licitação de aquisição de álcool e água oxigenada para atendimento da demanda da Polícia Científica do Paraná. DISPENSA ELETRÔNICA | C17: Raphael | D17: Grupo Auxiliar Administrativo | E17: TODAS | F17: 45250 | G17: R$ 16.715,60 | H17: 45516 | I17: 45520 | K17: 29/08/2024; 27/09/2024 | L17: CUSTEIO | M17: DISPENSA ELETRÔNICA | O17: FINALIZADO | P17: Regina de Paula Xavier Gomes | Q17: Anne Caroline Kambara Scholze | R17: PCP/DA/GAA/COMPRAS | S17: 45582 | T17: 30/01/2024 - Encaminhado ao Chefe do Financeiro para a atualização de informações orçamentárias21/02/2024 - Encaminhado ao SESP/AT via SESP/APC para continuação da tramitação21/05/2024- Encaminhado ao PCP/DA/GAA/COMPRAS para ciência e providências 13/06/2024 - Após disputa eletrônica enviado ao setor de compras/sesp29/07/2024- Encaminhado ao GAOFS para inserção de nota de empenho16/08/2024- Aguardando entrega29/08/2024- Material entregue 27/09/2024- Material entregue
A18: 20.651.072-2 | B18: Solicita a abertura de processo de licitação para aquisição de controle de acesso, com o intuito de atender à demanda da Unidade Tarumã | C18: Raphael | D18: PCP/DCV/DIV | E18: Tarumã | F18: 45099 | G18: R$ 587.051,94 | H18: 45665 | I18: 45686 | L18: INVESTIMENTO | M18: LICITAÇÃO | O18: TRAMITANDO | P18: Vinicius Gamarra Contieri | Q18: Camilla Borges Gazolla | R18: PCP/CWB/TAR/NECRO | S18: 45691 | T18: 26/01/2024 - Encaminhado ao Chefe da Divisão para a análise a manifestação 21/02/2024 - Encaminhado ao SESP/NFS via SESP/APC para continuação da tramitação 12/04/2024- Encaminhado à PGE/PRC para análise e deliberações 09/05/2024 - Encaminhado a unidade demandante para adequações 17/05/2024 - Encaminhado a SESP/APC para continuação da tramitação 03/02/2025 - Encaminhado ao Gestor do contrato para acompanhamento da execução das instalações | U18: Licitado e Homologado | V18: Empenho Imediato | X18: Dilação de prazo formalizada, os produtos deverão ser entregues ate dia 23/07/2025
A19: 20.402.562-2 | B19: FUNSUSP - AQUISIÇÃO, ATRAVÉS DE PROCEDIMENTO LICITATÓRIO, DE 20 POLTRONAS DE MASSAGEM | C19: Eduarda/Raphael | D19: CURITIBA | E19: TODAS | F19: 45049 | G19: R$ 287.230,60 | L19: INVESTIMENTO | M19: LICITAÇÃO | N19: FUNSUSP | O19: TRAMITANDO | P19: Vinicius Gamarra Contieri | Q19: Marceli dos Santos Gama | R19: PCP/DIR/DIRADM | S19: 45552 | T19: 22/05/2023 - Encaminhado ao PCP/DIV para análise e manifestação 20/06/2023 - Encaminhado a ao SESP/SL via Apoio Técnico da Polícia Científica para continuação da tramitação 11/07/2023 - Retorno para o GAA para providências 21/09/2023 - Encaminhado a ao SESP/SL via Apoio Técnico da Polícia Científica para continuação da tramitação 03/10/2023 - Enviado ao SESP/GOFS/FI para atualizações orçamentárias, sugerindo encaminhamento SESP/SL via SESP/APC 16/11/2023 - Retorno a PCP/DA/DIRADM tendo em vista que o protocolo chegou após a data limite para análise juridica.31/01/2024- Aguardando atualização de orçamento para envio ao SESP/APC 19/02/2024 - Encaminhado a SESP/NFS via SESP/APC para inclusão das informações orçamentarias e continuação da tramitação 01/04/2024 - Após nova atualização de valores, encaminhado à SESP/NFS via APC para inclusão de Inf. Orç, solicitando retorno para continuidade de instrução 09/05/2024 - Encaminhado a unidade demandante para adequações 11/07/2024 - Encaminhado para SESP/APC para continuação da tramitação | U19: não | V19: Sem Possibilidade de Empenho
A20: 21.582.699-6 | B20: Solicita a abertura de processo de licitação para aquisição de aparelhos de ar condicionado, com o intuito de atender à demanda da Polícia Científica do Paraná | C20: Raphael | D20: Grupo Auxiliar Administrativo | E20: TODAS | F20: 45307 | G20: R$ 448.316,80 | L20: INVESTIMENTO | M20: LICITAÇÃO | O20: TRAMITANDO | P20: Weverson Mendes de Lima | Q20: Augusto Pasqualini Neto | R20: SESP/SL | S20: 45574 | T20: 31/01/2024- Aguardando orçamentos para conclusão de cadastro em PCP/DA/GAA/COMPRAS07/06/2024- Encaminhado à Direção Administrativa para aprovação da despesa 04/10/2024-Com adequações encaminhado Setor de Licitações | U20: Licitando - PE90866/2024 - Talvez | V20: Indefinido
A21: 21.267.957-7 | B21: Manutenção nos microscópios comparadores balísticos Leica | C21: Raphael | D21: Grupo Auxiliar Administrativo | E21: Curitiba, Maringá, Londrina e Ponta Grossa | F21: 45231 | G21: R$ 168.750,00 | H21: 45454 | I21: 45456 | K21: 45569 | L21: INVESTIMENTO | M21: INEXIGIBILIDADE | O21: FINALIZADO | P21: Luiz Henrique da Silva Rotta | Q21: Luciano Gardano Elias Bucharles | R21: SESP/DG/NFS | S21: 45587 | T21: 30/01/2024 - Encaminhado ao Chefe do Financeiro para a atualização de informações orçamentárias09/04/2024- Encaminhado a PGE/AUT para análise e manifestação13/06/2024- Encaminhado para acompanhamento da entrega
A22: 20.634.920-4 | B22: Aquisição através de dispensa de licitação de cofres mecânicos relativo ao convênio federal 906.311/2020 para atendimento da Academia de Ciência Forense da Polícia Científica do Paraná. DISPENSA ELETRÔNICA | C22: Eduarda/Raphael | D22: ACF | E22: CURITIBA - ACADEMIA DE CIÊNCIAS FORENSES - ACF | F22: 45098 | G22: R$ 19.055,67 | L22: INVESTIMENTO | M22: DISPENSA ELETRÔNICA | N22: 906.311/2020 | O22: ARQUIVADO | P22: Ronald Silva Szafirski | Q22: Emílio Merino de Paz Júnior | R22: PCP/ACF/DIR | S22: 45355 | T22: 21/08/2023 - encaminhe-se à SESP/DG para apreciação e demais gestões 23/08/2023 - Encaminhado a SESP/DG para analise. 14/11/2023 - Encaminhado a SESP/COMPRAS via SESP/APC para continuação da tramitação 16/11/2023 - Encontra-se no setor de compras para analise do processo 05/12/2023 - Encontra-se SESP/DG em fase de autorizo19/01/2024 - Atualizado orçamento da empresa vencedora, encaminhado SESP/APC para continuidade
A23: 20.481.153-9 | B23: Solicitação de abertura de procedimento licitatório, visando a contratação de empresa especializada em prestação de serviços de locação de rastreadores veiculares, em substituição ao Protocolo 18.805.485-4, a fim de atender a demanda da Polícia Científica do Paraná. Apensado ao 21.828.937-1 | C23: Raphael | D23: CURITIBA | E23: TODAS | F23: 45062 | G23: R$ 164.160,00 | L23: CUSTEIO | M23: LICITAÇÃO | O23: Apensado | P23: Alessandro Burko Lopes | Q23: Philippe Alicio de Carvalho | R23: SESP/SL | S23: 45539 | T23: 31/05/2023 - Protocolo enviado DA/SEC para análise e manifestação 16/08/2023 - Enviado ao Apoio Técnico para continuidade de tramitação 16/11/2023 - Retorno a Origem tendo em vista que o protocolo chegou após a data limite para análise juridica. (Aguardar 2024)16/01/2024 - Com devidas adequações enviado PCP/DA/DIV06/02/2024 - Após adequações Prot devolvido ao Setor de Licitações.
A24: 21.672.986-2 | B24: SRP - Aquisição através do Registro de Preço do PE 26/2023, objetivando aquisição de material de Expediente - Grupo B para suprir a demanda da Polícia Científica do Paraná.VALIDADE DA ATA: 16/01/2025 | C24: Rodrigo Bianchini | D24: Grupo Auxiliar Administrativo | E24: TODAS | F24: 45324 | G24: R$ 4.059,60 | H24: 45362 | I24: 45392 | K24: 16/04/2024; 22/04/2024 | L24: CUSTEIO | M24: SRP Estadual | O24: FINALIZADO | P24: Rodrigo Taborda Ribas | Q24: Mauricio Catitas de Sousa | R24: PCP/DA/GAA/ALMOX | S24: 45454 | T24: 07/02/2024 - Encaminhado para o Chefe da Divisão Administrativa para análise e manifestação20/02/2024- Encaminhado ao GAOFS para informações orçamentárias e nota de reserva11/03/2024- Nota de empenho assinada 16/04/2024- Materiais recebidos22/04/2024- Materiais recebidos 07/05/2024- Encaminhado para liquidação e pagamento
A25: 21.680.216-0 | B25: SRP - Aquisição através do Registro de Preço do PE 28/2023, objetivando aquisição de material de Expediente - Grupo D para suprir a demanda da Polícia Científica do Paraná.VALIDADE DA ATA: 29/01/2025 | C25: Rodrigo Bianchini | D25: Grupo Auxiliar Administrativo | E25: TODAS | F25: 45327 | G25: R$ 1.817,48 | H25: 45377 | I25: 45393 | K25: 45407 | L25: CUSTEIO | M25: SRP Estadual | O25: FINALIZADO | P25: Rodrigo Taborda Ribas | Q25: Mauricio Catitas de Sousa | R25: SESP/DG/NFS | S25: 45498 | T25: 07/02/2024 - Encaminhado para o Chefe da Divisão Administrativa para análise e manifestação07/02/2024- Encaminhado ao GAOFS para informações orçamentárias e nota de reserva22/03/2024- Encaminhado para assinatura das notas de empenho25/04/2024- Materiais recebidos07/05/2024- Encaminhado para liquidação e pagamento
A26: 21.343.742-9 | B26: DISPENSA DE PROCEDIMENTO LICITATÓRIO POR INEXIGIBILIDADE PARA AQUISIÇÃO DE IMUNOENSAIOS CROMATOGRÁFICOS PARA A DETECÇÃO RÁPIDA DE HB PARA A IDENTIFICAÇÃO DE SANGUE E DE ANTÍGENO ESPECÍFICO DA PRÓSTATA (PSA) PARA A DENTIFICAÇÃO DE LÍQUIDO SEMINAL EM AMOSTRAS FORENSES, PARA ATENDER A DEMANDA DA SEÇÃO DE GENÉTICA MOLECULAR FORENSE DA POLÍCIA CIENTÍFICA DO PARANÁ. | C26: Eduarda/Raphael | D26: Genética | E26: Genética | F26: 45271 | G26: R$ 617.250,00 | H26: 45434 | I26: 45453 | K26: 45477 | L26: CUSTEIO | M26: INEXIGIBILIDADE | O26: FINALIZADO | P26: Jaqueline Andressa Machado Trentin Luz | Q26: Juliane Carlotto | R26: SESP/DG/NFS | S26: 45490 | T26: 16/01/2024 - Encaminhado para o Chefe da Divisão Administrativa para análise e manifestação06/02/2024 Após adequações restituído ao setor de Compras/SESP21/02/2024- Empenho emitido, encaminhado à SESP/DG para providências 15/03/2024 - Encaminhado a SESP/DEST/SC para continuação da tramitação30/04/2024- Contrato cadastrado no GMS; encaminhado ao GAOFS para providências 04/07/2024- Materiais entregues
A27: 21.555.831-2 | B27: Tem este o objetivo de solicitar a instauração de processo de licitação para aquisição de um Sistema de Cromatografia Líquida Acoplado a Espectrômetro de Massas de Alta Resolução (quadrupolo e tempo de voo - LC-qTOF), visando atender as necessidades de ampliação do escopo de análises analíticas realizadas pelos Laboratórios de Química Forense e Toxicologia Forense da Polícia Científica do Paraná. QUímica AGRO Forense | C27: Marcia | D27: Química | E27: Química | F27: 45330 | G27: R$ 3.694.713,38 | L27: INVESTIMENTO | M27: LICITAÇÃO | O27: ARQUIVADO | P27: Carolina Schmeiske da Graça | Q27: Raquel de Oliveira Vilhena | R27: PCP/CWB/TAR/QUIM | S27: 45491 | T27: 08/02/2024 - Abertura do processo licitatório03/05/2024- Encaminhado à SESP/DEST para providências
A28: 21.556.083-0 | B28: Solicita abertura de processo licitatório para aquisição de freezers e refrigeradores científicos, a fim de atender as demandas dos Laboratórios de Toxicologia Forense, Química Forense, Genética Forense e Central de Custódia da Polícia Científica do Paraná. | C28: Marcia | D28: Tarumã | E28: Toxicologia | F28: 45330 | G28: R$ 116.916,00 | L28: INVESTIMENTO | M28: LICITAÇÃO | O28: TRAMITANDO | P28: Carolina Schmeiske da Graça | Q28: Anna Carolina de Moraes Braga | R28: PCP/CWB/TAR/TOX | S28: 45467 | T28: 08/02/2024 - Abertura do processo licitatório 16/02/2024 - Encaminhado ao Divisional para análise e manifestação 26/03/2024 - Encaminhado a origem para adequação 04/06/2024- Encaminhado à SESP/SL para ciência e providências 21/06/2024- Encaminhado à origem para adequações | U28: Não - Enviado em 06/2024 para adequar e não retornou mais | V28: Indefinido
A29: 21.556.070-8 | B29: Tem este o objetivo de solicitar a instauração de processo de licitação para aquisição de um Sistema de Cromatografia iônica, visando atender as necessidades do Laboratórios de Química Forense e Toxicologia Forense da Polícia Científica do Paraná. Química Agro Forense | C29: Marcia | D29: Tarumã | E29: Química | F29: 45330 | G29: R$ 1.155.560,80 | L29: INVESTIMENTO | M29: LICITAÇÃO | O29: ARQUIVADO | P29: Carolina Schmeiske da Graça | Q29: Raquel de Oliveira Vilhena | R29: PCP/CWB/TAR/QUIM | S29: 45491 | T29: 08/02/2024 - Abertura do processo licitatório03/05/2024- Encaminhado à SESP/DEST para providências
A30: 21.706.486-4 | B30: Adesão à Ata de Registro de Preços - PE no 1142/2022, na modalidade carona, objetivando a aquisição de papel higiênico para suprir a demanda da Polícia Científica do Paraná. VALIDADE DA ATA: 01/04/2024 | C30: Amanda | D30: Grupo Auxiliar Administrativo | E30: Todos | F30: 45338 | G30: R$ 26.250,00 | L30: CUSTEIO | M30: SRP Estadual | O30: ARQUIVADO | P30: Leonardo Morrissy Hostin | Q30: Mauricio Catitas de Sousa | R30: PCP/DA/GAA/COMPRAS | S30: 45377 | T30: 20/02/2024- Encaminhado ao GAOFS para informação orçamentária e nota de reserva04/03/2024- Aguardando autorização da carona21/03/2024 - Não oha saldo para carona conforme informação do DECON
A31: 21.722.777-1 | B31: Dispensa de processo licitatório por inexigibilidade para aquisição de insumos para a Plataforma de Sequenciamento Massivo Paralelo (de nova geração) Ion Genestudio S5 e Ion Chef HID para atender a demanda da Seção de Genética Molecular Forense da Polícia Científica do Paraná. | C31: Marcia | D31: Tarumã | E31: Genética | F31: 45338 | G31: R$ 1.954.863,96 | L31: CUSTEIO | M31: INEXIGIBILIDADE | O31: APENSADO | P31: Luciellen D'avilla Giacomel Kobachuck | Q31: Pedro Henrqiue Canezin | R31: PCP/CWB/TAR/GENET | S31: 45544 | T31: 20/02/2024 - Encaminhado para o Chefe da Divisão Administrativa para análise e manifestaçãoEste protocolo está apensado ao 21.760.337-4
A32: 21.556.005-8 | B32: Tem este o objetivo de solicitar a instauração de processo de licitação para aquisição de um Sistema de Espectometria de Massas com plasma indutivamente acoplado (ICP/MS/MS), visando atender as necessidades de ampliação do escopo de análises analíticas realizadas pelos Laboratórios de Química Forense e Toxicologia Forense da Polícia Científica do Paraná. Química Agro Forense | C32: Marcia | D32: Tarumã | E32: Laboratórios de Química Forense e Toxicologia Forense | F32: 45314 | G32: R$ 2.539.153,47 | L32: INVESTIMENTO | M32: LICITAÇÃO | O32: ARQUIVADO | P32: Raquel de Oliveira Vilhena | Q32: Carolina Schmeiske da Graça | R32: PCP/CWB/TAR/QUIM | S32: 45491 | T32: 21/02/2024 - Encaminhado para o Chefe da Divisão Administrativa para análise e manifestação03/05/2024- Encaminhado à SESP/DEST para ciência e providências
A33: 21.631.509-0 | B33: SRP Cadeiras Giratórias - Aquisição através do Registro de Preço do PE 1415/2022, de Cadeiras Giratórias para atender a demanda das unidades da Polícia Científica do Paraná.VALIDADE DA ATA: 15/10/2024 | C33: Amanda | D33: Grupo Auxiliar Administrativo | E33: Tarumã | F33: 45322 | G33: R$ 13.621,21 | H33: 45509 | I33: 45510 | K33: 02/09/2024; 18/09/2024 | L33: INVESTIMENTO | M33: SRP Estadual | O33: FINALIZADO | P33: Adriano Saldanha Carneiro | Q33: Edgar Mallmann | R33: SESP/DG/NFS | S33: 45559 | T33: 19/02/2024 - Encaminhado a SESP/COMPRAS para continuação da tramitação 13/03/2024 - Encaminhado a SESP/DEST/SC para continuação da tramitação, bem como, elaboração da minuta de contrato30/04/2024- Retorno do processo à PCP/DA/GAA/COMPRAS para inserção de documentos 24/05/2024 - Encaminhado a AT/SESP via SESP/APC para continuação da tramitação 09/07/2024- Encaminhado ao GAOFS para inserção de nota de empenho08/08/2024- Aguardando entrega02/09/2024- Material entregue (FK)18/09/2024- Material entregue (EKOMB)
A34: 20.719.484-0 | B34: Licitação para aquisição de kits de Sistema de Vigilância - Circuito Fechado de TV (CFTV), sem instalação, para as sedes do Interior da Polícia Científica do Paraná | C34: Raphael | D34: Computação Forense | E34: Todas | F34: 45173 | G34: R$ 347.269,76 | L34: INVESTIMENTO | M34: LICITAÇÃO | O34: TRAMITANDO | P34: Leonardo de Ataide Jedneralski | Q34: Marcio Lopes Villanova e Silva | R34: PCP/DA/GAOFS | S34: 45692 | T34: 06/11/2023 - Retorno ao setor de compras PCP para adequações 16/11/2023 - Com as devidas alterações, restituído SESP/SL via SESP/APC 05/12/2023 - Encontra - se na assessoriaTécnica desta SESP para análise da redação de minuta do edital. 06/12/2023 - DEVOLVIDO A ORIGEM ENVIO FORA DO PRAZO - PCP/DIR/NI22/02/2024- Anexada a minuta padronizada da PGE, remetemos o procedimento à Assessoria Técnica Jurídica para providências cabíveis09/04/2024- Encaminhado ao PCP/DA/GAA/COMPRAS para ciência e providências 26/09/2024 - Com novas atualizações encaminhado ao setor financeiro para atualizações de informações orçamentárias. 04/02/2025 - Encaminhado para o PCP/DA/GAOFS para emissão da nota de empenho | U34: TALVEZ - CERTAME | PE 994/23 | PUBLICADO (abertura em 11/11/24) | V34: Indefinido
A35: 21.739.658-1 | B35: Aquisição de café por meio da Ata de Registro de Preços - PE no 1786/2022, para suprir a demanda da Polícia Científica do Paraná. | C35: Amanda | D35: Grupo Auxiliar Administrativo | E35: TODAS | F35: 45341 | G35: R$ 75.600,00 | H35: 45425 | L35: CUSTEIO | M35: SRP Estadual | O35: TRAMITANDO | P35: Leonardo Morrissy Hostin | Q35: Mauricio Catitas de Sousa | R35: PCP/DA/GAA/COMPRAS | S35: 45582
A36: 21.728.149-0 | B36: Contratação direta por dispensa de licitação para aquisição de rolos de papel alumínio com 7,5 m de comprimento e 30 cm de largura para atender a demanda das Seções de Química Forense e Toxicologia Forense, da Polícia Científica do Paraná. | C36: Eduarda | D36: Grupo Auxiliar Administrativo | E36: Seção de Química e Toxicologia Forense | F36: 45341 | G36: R$ 510,94 | H36: 45425 | I36: 45433 | K36: 45439 | L36: CUSTEIO | M36: DISPENSA DE LICITAÇÃO | O36: FINALIZADO | P36: Ricardo Maia | Q36: Paula Eidt Fornari | R36: SESP/DG/NFS | S36: 45498 | T36: 28/02/2024 - Encaminhado a PCP/DIV para análise e manifestação 12/03/2024 - Encaminhado ao SESP/COMPRAS para continuação da tramitação por menor valor 04/04/2024 - Encaminhado ao SESP/COMPRAS para continuação da tramitação29/04/2024- Encaminhado para assinatura da Nota de Empenho21/05/2024- Empenho e O.C encaminhados ao fornecedor- Aguardando entrega03/06/2024- Encaminhado para liquidação e pagamento
A37: 21.399.689-4 | B37: Dispensa de Licitação, na modalidade Eletrônica, para aquisição de Caixa de Arquivo Morto em atendimento da demanda da Polícia Científica do Paraná. DISPENSA ELETRÔNICA | C37: Eduarda | D37: Grupo Auxiliar Administrativo | E37: Todas | F37: 45259 | G37: R$ 11.504,00 | H37: 45567 | I37: 45512 | K37: 45552 | L37: CUSTEIO | M37: DISPENSA ELETRÔNICA | O37: FINALIZADO | P37: Beatriz Rossi Canuto de Menezes Rodrigues | Q37: Mauricio Catitas de Souza | R37: SESP/DG/NFS | S37: 45575 | T37: 06/12/2023 - ENCAMINHADO EM 04/12 PARA NFS/OR para assinatura das informações orçamentárias 13/12/2023 - Encaminhado ao PCP/DA/DIV para ciência e posterior envio até o dia 02/01/2024 22/01/2024 - Encaminhado ao PCP/DA/GAOFS para continuação da tramitação 23/02/2024 - Encaminhado ao SESP/COMPRAS para continuação da tramitação18/03/2024- Encaminhado à Assessoria Técnica da SESP solicitando autorizção do ordenador de despesas 26/06/2024 - Encaminhado para SESP/COMPRAS para continuação da tramitação 08/08/2024- Aguardando entrega17/09/2024- Material entregue
